03/18/2021 07:41:04 PM: ERROR: Task exception was never retrieved
future: <Task finished name='Task-839' coro=<User.__double_edit_waiting() done, defined at C:\Users\wsu\PycharmProjects\telegram-bot\base\user_telegram.py:40> exception=TimeoutError()>: base_events.py
Traceback (most recent call last):
  File "C:\Users\wsu\PycharmProjects\telegram-bot\base\user_telegram.py", line 41, in __double_edit_waiting
    await conver.wait_event(events.MessageEdited(from_users=self.bot))
  File "c:\users\wsu\pycharmprojects\telegram-bot\venv\lib\site-packages\telethon\tl\custom\conversation.py", line 339, in wait_event
    return await self._get_result(future, start_time, timeout, self._custom, counter)
  File "C:\Users\wsu\anaconda3\lib\asyncio\tasks.py", line 490, in wait_for
    raise exceptions.TimeoutError()
asyncio.exceptions.TimeoutError
03/18/2021 07:41:04 PM: ERROR: Task exception was never retrieved
future: <Task finished name='Task-840' coro=<User.__double_new_waiting() done, defined at C:\Users\wsu\PycharmProjects\telegram-bot\base\user_telegram.py:33> exception=TimeoutError()>: base_events.py
Traceback (most recent call last):
  File "C:\Users\wsu\PycharmProjects\telegram-bot\base\user_telegram.py", line 34, in __double_new_waiting
    await conver.wait_event(events.NewMessage(from_users=self.bot))
  File "c:\users\wsu\pycharmprojects\telegram-bot\venv\lib\site-packages\telethon\tl\custom\conversation.py", line 339, in wait_event
    return await self._get_result(future, start_time, timeout, self._custom, counter)
  File "C:\Users\wsu\anaconda3\lib\asyncio\tasks.py", line 490, in wait_for
    raise exceptions.TimeoutError()
asyncio.exceptions.TimeoutError
03/18/2021 08:01:27 PM: ERROR: Task exception was never retrieved
future: <Task finished name='Task-7951' coro=<UpdateMethods._dispatch_update() done, defined at c:\users\wsu\pycharmprojects\telegram-bot\venv\lib\site-packages\telethon\client\updates.py:383> exception=InvalidStateError('invalid state')>: base_events.py
Traceback (most recent call last):
  File "c:\users\wsu\pycharmprojects\telegram-bot\venv\lib\site-packages\telethon\client\updates.py", line 426, in _dispatch_update
    await conv._check_custom(built)
  File "c:\users\wsu\pycharmprojects\telegram-bot\venv\lib\site-packages\telethon\tl\custom\conversation.py", line 352, in _check_custom
    fut.set_result(inst)
asyncio.exceptions.InvalidStateError: invalid state
03/19/2021 11:29:35 AM: ERROR: Task exception was never retrieved
future: <Task finished name='Task-776' coro=<User.__double_edit_waiting() done, defined at C:\Users\wsu\PycharmProjects\telegram-bot\base\user_telegram.py:40> exception=TimeoutError()>: base_events.py
Traceback (most recent call last):
  File "C:\Users\wsu\PycharmProjects\telegram-bot\base\user_telegram.py", line 41, in __double_edit_waiting
    await conver.wait_event(events.MessageEdited(from_users=self.bot))
  File "c:\users\wsu\pycharmprojects\telegram-bot\venv\lib\site-packages\telethon\tl\custom\conversation.py", line 339, in wait_event
    return await self._get_result(future, start_time, timeout, self._custom, counter)
  File "C:\Users\wsu\anaconda3\lib\asyncio\tasks.py", line 490, in wait_for
    raise exceptions.TimeoutError()
asyncio.exceptions.TimeoutError
03/19/2021 11:29:35 AM: ERROR: Task exception was never retrieved
future: <Task finished name='Task-777' coro=<User.__double_new_waiting() done, defined at C:\Users\wsu\PycharmProjects\telegram-bot\base\user_telegram.py:33> exception=TimeoutError()>: base_events.py
Traceback (most recent call last):
  File "C:\Users\wsu\PycharmProjects\telegram-bot\base\user_telegram.py", line 34, in __double_new_waiting
    await conver.wait_event(events.NewMessage(from_users=self.bot))
  File "c:\users\wsu\pycharmprojects\telegram-bot\venv\lib\site-packages\telethon\tl\custom\conversation.py", line 339, in wait_event
    return await self._get_result(future, start_time, timeout, self._custom, counter)
  File "C:\Users\wsu\anaconda3\lib\asyncio\tasks.py", line 490, in wait_for
    raise exceptions.TimeoutError()
asyncio.exceptions.TimeoutError
03/19/2021 11:31:51 AM: ERROR: Task exception was never retrieved
future: <Task finished name='Task-1211' coro=<User.__double_edit_waiting() done, defined at C:\Users\wsu\PycharmProjects\telegram-bot\base\user_telegram.py:40> exception=TimeoutError()>: base_events.py
Traceback (most recent call last):
  File "C:\Users\wsu\PycharmProjects\telegram-bot\base\user_telegram.py", line 41, in __double_edit_waiting
    await conver.wait_event(events.MessageEdited(from_users=self.bot))
  File "c:\users\wsu\pycharmprojects\telegram-bot\venv\lib\site-packages\telethon\tl\custom\conversation.py", line 339, in wait_event
    return await self._get_result(future, start_time, timeout, self._custom, counter)
  File "C:\Users\wsu\anaconda3\lib\asyncio\tasks.py", line 490, in wait_for
    raise exceptions.TimeoutError()
asyncio.exceptions.TimeoutError
03/19/2021 11:31:51 AM: ERROR: Task exception was never retrieved
future: <Task finished name='Task-1212' coro=<User.__double_new_waiting() done, defined at C:\Users\wsu\PycharmProjects\telegram-bot\base\user_telegram.py:33> exception=TimeoutError()>: base_events.py
Traceback (most recent call last):
  File "C:\Users\wsu\PycharmProjects\telegram-bot\base\user_telegram.py", line 34, in __double_new_waiting
    await conver.wait_event(events.NewMessage(from_users=self.bot))
  File "c:\users\wsu\pycharmprojects\telegram-bot\venv\lib\site-packages\telethon\tl\custom\conversation.py", line 339, in wait_event
    return await self._get_result(future, start_time, timeout, self._custom, counter)
  File "C:\Users\wsu\anaconda3\lib\asyncio\tasks.py", line 490, in wait_for
    raise exceptions.TimeoutError()
asyncio.exceptions.TimeoutError
03/20/2021 07:50:17 PM: WARNING: SKIP Scenario check NBP(user) -- @1.1 : not worktime: model.py
03/20/2021 07:50:30 PM: WARNING: SKIP Scenario check NBP(user) -- @1.2 : not worktime: model.py
03/20/2021 07:50:44 PM: WARNING: SKIP Scenario check NBP(user) -- @1.3 : not worktime: model.py
03/20/2021 07:54:08 PM: WARNING: SKIP Scenario check NBP(user) -- @1.1 : not worktime: model.py
03/20/2021 07:54:21 PM: WARNING: SKIP Scenario check NBP(user) -- @1.2 : not worktime: model.py
03/20/2021 07:54:35 PM: WARNING: SKIP Scenario check NBP(user) -- @1.3 : not worktime: model.py
03/20/2021 08:02:40 PM: WARNING: SKIP Scenario check NBP(user) -- @1.1 : not worktime: model.py
03/20/2021 08:06:37 PM: WARNING: SKIP Scenario check NBP(user) -- @1.1 : not worktime: model.py
03/20/2021 08:06:50 PM: WARNING: SKIP Scenario check NBP(user) -- @1.2 : not worktime: model.py
03/20/2021 08:07:04 PM: WARNING: SKIP Scenario check NBP(user) -- @1.3 : not worktime: model.py
03/20/2021 08:07:24 PM: WARNING: SKIP Scenario cancel NBP -- @1.1 : not worktime: model.py
03/20/2021 08:07:44 PM: WARNING: SKIP Scenario cancel NBP -- @1.2 : not worktime: model.py
03/20/2021 08:08:04 PM: WARNING: SKIP Scenario cancel NBP -- @1.3 : not worktime: model.py
03/20/2021 09:42:41 PM: WARNING: SKIP Scenario check NBP(user) -- @1.1 : not worktime: model.py
03/20/2021 09:42:54 PM: WARNING: SKIP Scenario check NBP(user) -- @1.2 : not worktime: model.py
03/20/2021 09:43:07 PM: WARNING: SKIP Scenario check NBP(user) -- @1.3 : not worktime: model.py
03/20/2021 09:43:28 PM: WARNING: SKIP Scenario cancel NBP -- @1.1 : not worktime: model.py
03/20/2021 09:43:48 PM: WARNING: SKIP Scenario cancel NBP -- @1.2 : not worktime: model.py
03/20/2021 09:44:09 PM: WARNING: SKIP Scenario cancel NBP -- @1.3 : not worktime: model.py
03/21/2021 09:11:15 AM: ERROR: Support bot does not work from 08:00 to 23:00 UTC: functions.py
03/21/2021 11:39:32 AM: ERROR: The test session isn't created: functions.py
03/21/2021 11:54:35 AM: ERROR: The test session isn't created: functions.py
